Workbook

Sheet Species_database
A1: plantname | B1: genus | C1: species | D1: SPCD | E1: type | F1: WoodDensity | G1: CA_vol_eqn | H1: WOR_vol_eqn | I1: WWA_vol_eqn | J1: EOR_vol_eqn | K1: EWA_vol_eqn | L1: CA_BarkBiomass_eqn | M1: WOR_BarkBiomass_eqn | N1: WWA_BarkBiomass_eqn | O1: EOR_BarkBiomass_eqn | P1: EWA_BarkBiomass_eqn | Q1: CA_BranchBiomass_eqn | R1: WOR_BranchBiomass_eqn | S1: WWA_BranchBiomass_eqn | T1: EOR_BranchBiomass_eqn | U1: EWA_BranchBiomass_eqn
A2: Valley or 'california white' oak | B2: Quercus | C2: lobata | D2: 821 | E2: hardwood | F2: 34.32 | G2: 35 | L2: na | M2: na | N2: na | O2: na | P2: na | Q2: na | R2: na | S2: na | T2: na | U2: na
A3: Bigleaf maple | B3: Acer | C3: macrophyllum | D3: 312 | E3: hardwood | F3: 27.46 | G3: 37 | L3: na | M3: na | N3: 29 | O3: na | P3: 29 | Q3: na | R3: na | S3: 27 | T3: na | U3: 27
A4: Boxelder | B4: Acer | C4: negundo | D4: 313 | E4: hardwood | F4: 26.21 | G4: 38 | L4: na | M4: na | N4: 29 | O4: na | P4: 29 | Q4: na | R4: na | S4: 16 | T4: na | U4: 16
A5: Oregon ash | B5: Fraxinus | C5: latifolia | D5: 542 | E5: hardwood | F5: 31.2 | G5: 38 | L5: na | M5: na | N5: 39 | O5: na | P5: 39 | Q5: na | R5: na | S5: 16 | T5: na | U5: 16
A6: N. california black walnut | B6: Juglans | C6: hindisii | D6: 603 | E6: hardwood | F6: 27.46 | G6: 38 | L6: na | M6: na | N6: na | O6: na | P6: na | Q6: na | R6: na | S6: na | T6: na | U6: na
A7: Blue oak | B7: Quercus | C7: douglasii | D7: 807 | E7: hardwood | F7: 36.82 | G7: 39 | L7: na | M7: na | N7: na | O7: na | P7: na | Q7: na | R7: na | S7: na | T7: na | U7: na
A8: Unkown willow | B8: Salix | C8: spp. | D8: 920 | E8: hardwood | F8: 22.46 | G8: 40 | L8: na | M8: 34 | N8: 34 | O8: 34 | P8: 34 | Q8: na | R8: na | S8: na | T8: na | U8: na
A9: Unknown tree | B9: Unknown | C9: spp. | D9: 999 | E9: hardwood | F9: 32.45 | G9: 41 | L9: na | M9: 39 | N9: 39 | O9: 39 | P9: 39 | Q9: na | R9: 16 | S9: 16 | T9: 16 | U9: 16
A10: California buckeye | B10: Aesculus | C10: californica | D10: 333 | E10: hardwood | F10: 20.59 | G10: 43 | L10: na | M10: na | N10: na | O10: na | P10: na | Q10: na | R10: na | S10: na | T10: na | U10: na
A11: California live oak | B11: Quercus | C11: agrifolia | D11: 801 | E11: hardwood | F11: 36.82 | G11: 43 | L11: na | M11: na | N11: na | O11: na | P11: na | Q11: na | R11: na | S11: na | T11: na | U11: na
A12: Interior live oak | B12: Quercus | C12: wislizeni | D12: 839 | E12: hardwood | F12: 36.82 | G12: 44 | L12: na | M12: na | N12: na | O12: na | P12: na | Q12: na | R12: na | S12: na | T12: na | U12: na
A13: Tanoak | B13: Notholithocarpus | C13: densiflorus | D13: 631 | E13: hardwood | F13: 36.19 | G13: 34 | L13: na | M13: na | N13: na | O13: na | P13: na | Q13: na | R13: na | S13: na | T13: na | U13: na
A14: California sycamore | B14: Platanus | C14: racemosa | D14: 730 | E14: hardwood | F14: 28.7 | G14: 42 | L14: na | M14: 37 | N14: 37 | O14: 37 | P14: 37 | Q14: na | R14: na | S14: na | T14: na | U14: na
A15: Golden chinkapin | B15: Chrysolepis | C15: chrysophylla | D15: 431 | E15: hardwood | F15: 26.21 | G15: 32 | L15: na | M15: na | N15: 32 | O15: na | P15: na | Q15: na | R15: na | S15: 29 | T15: na | U15: na
A16: Canyon live oak | B16: Quercus | C16: chrysolepis | D16: 801 | E16: hardwood | F16: 43.68 | G16: 42 | L16: na | M16: na | N16: na | O16: na | P16: na | Q16: na | R16: na | S16: na | T16: na | U16: na
A17: Unknown hardwood | B17: Hardwood | C17: spp. | D17: 998 | E17: hardwood | F17: 32.45 | G17: 41 | L17: na | M17: 20 | N17: 20 | O17: 20 | P17: 20 | Q17: na | R17: 16 | S17: 16 | T17: 16 | U17: 16
A18: Fremont poplar / Fremont cottonwood | B18: Populus | C18: fremontii | D18: 748 | E18: hardwood | F18: 25.58 | G18: 27 | L18: 18 | M18: na | N18: na | O18: na | P18: na | Q18: 5 | R18: na | S18: na | T18: na | U18: na
A19: Monterey cypress | B19: Hesperocyparis | C19: macrocarpa | D19: 54 | E19: softwood | F19: 25.58 | G19: 19 | L19: 13 | M19: na | N19: na | O19: na | P19: na | Q19: 10 | R19: na | S19: na | T19: na | U19: na
A20: Douglas-fir | B20: Pseudotsuga | C20: menziesii | D20: 202 | E20: softwood | F20: 28.08 | G20: 3 | L20: 8 | M20: na | N20: na | O20: na | P20: na | Q20: 6 | R20: 6 | S20: 6 | T20: 22 | U20: 22
A21: Ponderosa pine | B21: Pinus | C21: ponderosa | D21: 122 | E21: softwood | F21: 23.71 | G21: 5 | L21: 9 | M21: 9 | N21: 9 | O21: 9 | P21: 9 | Q21: 7 | R21: 7 | S21: 7 | T21: 7 | U21: 7
A22: California nutmeg | B22: Torreya | C22: californica | D22: 251 | E22: softwood | F22: 25.58 | G22: 8 | L22: 13 | M22: na | N22: na | O22: na | P22: na | Q22: 10 | R22: na | S22: na | T22: na | U22: na
A23: Sugar pine | B23: Pinus | C23: lambertiana | D23: 117 | E23: softwood | F23: 21.22 | G23: 20 | H23: 20 | I23: na | J23: 20 | K23: na | L23: 10 | M23: 10 | N23: na | O23: 10 | P23: na | Q23: 8 | R23: 8 | S23: na | T23: 8 | U23: na
A24: Black cottonwood | B24: Populus | C24: trichocarpa | D24: 747 | E24: hardwood | F24: 19.34 | G24: 27 | L24: 28 | M24: 28 | N24: 28 | O24: 28 | P24: 28 | Q24: 15 | R24: 15 | S24: 15 | T24: 15 | U24: 15
A25: Quaking aspen | B25: Populus | C25: tremuloides | D25: 746 | E25: hardwood | F25: 21.84 | G25: 28 | L25: 18 | M25: 18 | N25: 18 | O25: 18 | P25: 18 | Q25: 14 | R25: 14 | S25: 14 | T25: 14 | U25: 14
A26: Unknown conifer | B26: Conifer | C26: spp. | D26: 289/299 | E26: softwood | F26: 25.58 | G26: 17 | H26: 17 | I26: 17 | J26: 17 | K26: 17 | L26: 21 | M26: 21 | N26: 21 | O26: 21 | P26: 21 | Q26: 24 | R26: 24 | S26: 24 | T26: 24 | U26: 24

Sheet Eqn_checklist
A1: Eqn# | B1: Type | C1: Drafted | D1: Checked
A2: 25 | B2: Hardwood volume
A3: 26 | B3: Hardwood volume | F3: Total equations | G3: % Drafted | H3: % Complete
A4: 27 | B4: Hardwood volume | C4: =COUNTIF(Species_database!$G$2:$G50, A4) > 0 -> TRUE | D4: TRUE | F4: =COUNTA(A2:A200) -> 116 | G4: =COUNTA(C2:C200)/F4 -> 0.27586207 | H4: =COUNTA(D2:D200)/F4 -> 0.24137931
A5: 28 | B5: Hardwood volume | C5: =COUNTIF(Species_database!$G$2:$G51, A5) > 0 -> TRUE | D5: TRUE
A6: 29 | B6: Hardwood volume
A7: 30 | B7: Hardwood volume
A8: 31 | B8: Hardwood volume
A9: 32 | B9: Hardwood volume | C9: =COUNTIF(Species_database!$G$2:$G55, A9) > 0 -> TRUE | D9: TRUE
A10: 33 | B10: Hardwood volume
A11: 34 | B11: Hardwood volume | C11: =COUNTIF(Species_database!$G$2:$G57, A11) > 0 -> TRUE | D11: TRUE
A12: 35 | B12: Hardwood volume | C12: =COUNTIF(Species_database!$G$2:$G58, A12) > 0 -> TRUE | D12: TRUE
A13: 36 | B13: Hardwood volume
A14: 37 | B14: Hardwood volume | C14: =COUNTIF(Species_database!$G$2:$G60, A14) > 0 -> TRUE | D14: TRUE
A15: 38 | B15: Hardwood volume | C15: =COUNTIF(Species_database!$G$2:$G61, A15) > 0 -> TRUE | D15: TRUE
A16: 39 | B16: Hardwood volume | C16: =COUNTIF(Species_database!$G$2:$G62, A16) > 0 -> TRUE | D16: TRUE
A17: 40 | B17: Hardwood volume | C17: =COUNTIF(Species_database!$G$2:$G63, A17) > 0 -> TRUE | D17: TRUE
A18: 41 | B18: Hardwood volume | C18: =COUNTIF(Species_database!$G$2:$G64, A18) > 0 -> TRUE | D18: TRUE
A19: 42 | B19: Hardwood volume | C19: =COUNTIF(Species_database!$G$2:$G65, A19) > 0 -> TRUE | D19: TRUE
A20: 43 | B20: Hardwood volume | C20: =COUNTIF(Species_database!$G$2:$G66, A20) > 0 -> TRUE | D20: TRUE
A21: 44 | B21: Hardwood volume | C21: =COUNTIF(Species_database!$G$2:$G67, A21) > 0 -> TRUE | D21: TRUE
A22: 45 | B22: Hardwood volume
A23: 46 | B23: Hardwood volume
A24: 1 | B24: Softwood volume
A25: 2 | B25: Softwood volume
A26: 3 | B26: Softwood volume | C26: =COUNTIF(Species_database!$G$2:$G72, A26) > 0 -> TRUE | D26: TRUE
A27: 4 | B27: Softwood volume
A28: 5 | B28: Softwood volume | C28: =COUNTIF(Species_database!$G$2:$G74, A28) > 0 -> TRUE | D28: TRUE
A29: 6 | B29: Softwood volume
A30: 7 | B30: Softwood volume | C30: =COUNTIF(Species_database!$G$2:$G76, A30) > 0 -> FALSE
A31: 8 | B31: Softwood volume | C31: =COUNTIF(Species_database!$G$2:$G77, A31) > 0 -> TRUE | D31: TRUE
A32: 9 | B32: Softwood volume
A33: 10 | B33: Softwood volume
A34: 11 | B34: Softwood volume
A35: 12 | B35: Softwood volume
A36: 13 | B36: Softwood volume
A37: 14 | B37: Softwood volume
A38: 14.1 | B38: Softwood volume
A39: 14.2 | B39: Softwood volume
A40: 15 | B40: Softwood volume
...

Sheet Species_checklist
A1: SpeciesCode | B1: Species Name | C1: Database filled | D1: Eqns written
A2: 10 | B2: fir spp.
A3: 11 | B3: Pacific silver fir
A4: 14 | B4: bristlecone fir
A5: 15 | B5: white fir
A6: 17 | B6: grand fir
A7: 19 | B7: subalpine fir
A8: 20 | B8: California red fir
A9: 21 | B9: Shasta red fir
A10: 22 | B10: noble fir
A11: 41 | B11: Port-Orford-cedar
A12: 42 | B12: Alaska yellow-cedar
A13: 50 | B13: Cypress spp
... A99: 818 | B99: California black oak
